Workbook

Sheet READ ME
A1: What this workbook is
A3: A live re-computation of the equal-weight, fully-invested backtest from
A4: the Research OS engine. Every NAV, cost and metric is an Excel FORMULA,
A5: not a pasted number. Click any cell and read the formula bar.
A7: How to check the engine with it
A9: 1. On the 'Backtest' sheet, look at column W (NAV difference).
A10: That is Excel's NAV minus the engine's NAV, on every trading day.
A11: Every row should read 0.00E+00 or something around 1e-15.
A12: 2. The 'Metrics' sheet reports the largest difference across all rows.
A13: 3. Pick any rebalance row (column G = 1) and check by hand:
A14: traded (P) = sum over the five sleeves of
A15: |target weight - drifted weight|
... A43: and no amount of cross-checking retires them.

Sheet Prices
A1: Date | B1: NIFTY500 MOMENTUM 50 | C1: NIFTY500 QUALITY 50 | D1: NIFTY500 VALUE 50 | E1: NIFTY500 LOW VOLATILITY 50 | F1: NIFTY ALPHA 50
A2: 38443 | B2: 1000 | C2: 1000 | D2: 1000 | E2: 1000 | F2: 1589.39
A3: 38446 | B3: 1015.42 | C3: 996.81 | D3: 994.18 | E3: 1002.46 | F3: 1607.36
A4: 38447 | B4: 1008.76 | C4: 985.34 | D4: 980.92 | E4: 998.47 | F4: 1598.08
A5: 38448 | B5: 1025.13 | C5: 994.42 | D5: 1001.34 | E5: 1003.99 | F5: 1619.39
A6: 38449 | B6: 1019.09 | C6: 992.09 | D6: 1001.88 | E6: 999.23 | F6: 1622.37
A7: 38450 | B7: 1009.69 | C7: 982.17 | D7: 996.57 | E7: 989.93 | F7: 1605.66
A8: 38453 | B8: 999.58 | C8: 973.97 | D8: 990.16 | E8: 982.73 | F8: 1582.9
A9: 38454 | B9: 1005.32 | C9: 982.55 | D9: 996.6 | E9: 990.83 | F9: 1597.09
A10: 38455 | B10: 1005.21 | C10: 982.54 | D10: 997.5 | E10: 994.08 | F10: 1598.94
A11: 38457 | B11: 970.69 | C11: 948.26 | D11: 971.11 | E11: 970.63 | F11: 1552.51
A12: 38460 | B12: 958.05 | C12: 934.03 | D12: 965.13 | E12: 960.09 | F12: 1530.89
A13: 38461 | B13: 957.1 | C13: 922.97 | D13: 955.63 | E13: 956.23 | F13: 1526.52
... A5257: 46184 | B5257: 51363.45 | C5257: 18860.25 | D5257: 16046.6 | E5257: 21370.75 | F5257: 50749.5

Sheet Backtest
A1: Date | B1: Price: NIFTY500 MOMENTUM 50 | C1: Price: NIFTY500 QUALITY 50 | D1: Price: NIFTY500 VALUE 50 | E1: Price: NIFTY500 LOW VOLATILITY 50 | F1: Price: NIFTY ALPHA 50 | G1: Rebal? | H1: Started | I1: NAV before cost | J1: Units: NIFTY500 MOMENTUM 50 | K1: Units: NIFTY500 QUALITY 50 | L1: Units: NIFTY500 VALUE 50 | M1: Units: NIFTY500 LOW VOLATILITY 50 | N1: Units: NIFTY ALPHA 50 | O1: Cash | P1: Traded (L1) | Q1: Cost | R1: NAV | S1: Daily return | T1: Peak | U1: Drawdown | V1: ENGINE NAV | W1: NAV difference
A2: 38443 | B2: =Prices!B2 | C2: =Prices!C2 | D2: =Prices!D2 | E2: =Prices!E2 | F2: =Prices!F2 | G2: =IF(AND(0>=16,TEXT(A2,"yyyy-mm")<>TEXT(A3,"yyyy-mm")),1,0) | H2: =G2 | I2: 1 | J2: 0 | K2: 0 | L2: 0 | M2: 0 | N2: 0 | O2: 1 | P2: 0 | Q2: 0 | R2: 1 | S2: 0 | T2: 1 | U2: 0 | V2: 1 | W2: =R2-V2
A3: 38446 | B3: =Prices!B3 | C3: =Prices!C3 | D3: =Prices!D3 | E3: =Prices!E3 | F3: =Prices!F3 | G3: =IF(AND(1>=16,TEXT(A3,"yyyy-mm")<>TEXT(A4,"yyyy-mm")),1,0) | H3: =IF(OR(H2=1,G3=1),1,0) | I3: =IF(H2=0,1,SUMPRODUCT(J2:N2,B3:F3)+O2*(1+0.00023125256064071564)) | J3: =IF(G3=1,0.2*R3/B3,J2) | K3: =IF(G3=1,0.2*R3/C3,K2) | L3: =IF(G3=1,0.2*R3/D3,L2) | M3: =IF(G3=1,0.2*R3/E3,M2) | N3: =IF(G3=1,0.2*R3/F3,N2) | O3: =IF(G3=1,R3*(1-1.0),IF(H2=0,1,O2*(1+0.00023125256064071564))) | P3: =IF(G3=1,IF(H2=0,1,ABS(0.2-J2*B3/I3)+ABS(0.2-K2*C3/I3)+ABS(0.2-L2*D3/I3)+ABS(0.2-M2*E3/I3)+ABS(0.2-N2*F3/I3)),0) | Q3: =P3*0.0015 | R3: =I3*(1-Q3) | S3: =R3/R2-1 | T3: =MAX(T2,R3) | U3: =R3/T3-1 | V3: 1 | W3: =R3-V3
A4: 38447 | B4: =Prices!B4 | C4: =Prices!C4 | D4: =Prices!D4 | E4: =Prices!E4 | F4: =Prices!F4 | G4: =IF(AND(2>=16,TEXT(A4,"yyyy-mm")<>TEXT(A5,"yyyy-mm")),1,0) | H4: =IF(OR(H3=1,G4=1),1,0) | I4: =IF(H3=0,1,SUMPRODUCT(J3:N3,B4:F4)+O3*(1+0.00023125256064071564)) | J4: =IF(G4=1,0.2*R4/B4,J3) | K4: =IF(G4=1,0.2*R4/C4,K3) | L4: =IF(G4=1,0.2*R4/D4,L3) | M4: =IF(G4=1,0.2*R4/E4,M3) | N4: =IF(G4=1,0.2*R4/F4,N3) | O4: =IF(G4=1,R4*(1-1.0),IF(H3=0,1,O3*(1+0.00023125256064071564))) | P4: =IF(G4=1,IF(H3=0,1,ABS(0.2-J3*B4/I4)+ABS(0.2-K3*C4/I4)+ABS(0.2-L3*D4/I4)+ABS(0.2-M3*E4/I4)+ABS(0.2-N3*F4/I4)),0) | Q4: =P4*0.0015 | R4: =I4*(1-Q4) | S4: =R4/R3-1 | T4: =MAX(T3,R4) | U4: =R4/T4-1 | V4: 1 | W4: =R4-V4
A5: 38448 | B5: =Prices!B5 | C5: =Prices!C5 | D5: =Prices!D5 | E5: =Prices!E5 | F5: =Prices!F5 | G5: =IF(AND(3>=16,TEXT(A5,"yyyy-mm")<>TEXT(A6,"yyyy-mm")),1,0) | H5: =IF(OR(H4=1,G5=1),1,0) | I5: =IF(H4=0,1,SUMPRODUCT(J4:N4,B5:F5)+O4*(1+0.00023125256064071564)) | J5: =IF(G5=1,0.2*R5/B5,J4) | K5: =IF(G5=1,0.2*R5/C5,K4) | L5: =IF(G5=1,0.2*R5/D5,L4) | M5: =IF(G5=1,0.2*R5/E5,M4) | N5: =IF(G5=1,0.2*R5/F5,N4) | O5: =IF(G5=1,R5*(1-1.0),IF(H4=0,1,O4*(1+0.00023125256064071564))) | P5: =IF(G5=1,IF(H4=0,1,ABS(0.2-J4*B5/I5)+ABS(0.2-K4*C5/I5)+ABS(0.2-L4*D5/I5)+ABS(0.2-M4*E5/I5)+ABS(0.2-N4*F5/I5)),0) | Q5: =P5*0.0015 | R5: =I5*(1-Q5) | S5: =R5/R4-1 | T5: =MAX(T4,R5) | U5: =R5/T5-1 | V5: 1 | W5: =R5-V5
A6: 38449 | B6: =Prices!B6 | C6: =Prices!C6 | D6: =Prices!D6 | E6: =Prices!E6 | F6: =Prices!F6 | G6: =IF(AND(4>=16,TEXT(A6,"yyyy-mm")<>TEXT(A7,"yyyy-mm")),1,0) | H6: =IF(OR(H5=1,G6=1),1,0) | I6: =IF(H5=0,1,SUMPRODUCT(J5:N5,B6:F6)+O5*(1+0.00023125256064071564)) | J6: =IF(G6=1,0.2*R6/B6,J5) | K6: =IF(G6=1,0.2*R6/C6,K5) | L6: =IF(G6=1,0.2*R6/D6,L5) | M6: =IF(G6=1,0.2*R6/E6,M5) | N6: =IF(G6=1,0.2*R6/F6,N5) | O6: =IF(G6=1,R6*(1-1.0),IF(H5=0,1,O5*(1+0.00023125256064071564))) | P6: =IF(G6=1,IF(H5=0,1,ABS(0.2-J5*B6/I6)+ABS(0.2-K5*C6/I6)+ABS(0.2-L5*D6/I6)+ABS(0.2-M5*E6/I6)+ABS(0.2-N5*F6/I6)),0) | Q6: =P6*0.0015 | R6: =I6*(1-Q6) | S6: =R6/R5-1 | T6: =MAX(T5,R6) | U6: =R6/T6-1 | V6: 1 | W6: =R6-V6
A7: 38450 | B7: =Prices!B7 | C7: =Prices!C7 | D7: =Prices!D7 | E7: =Prices!E7 | F7: =Prices!F7 | G7: =IF(AND(5>=16,TEXT(A7,"yyyy-mm")<>TEXT(A8,"yyyy-mm")),1,0) | H7: =IF(OR(H6=1,G7=1),1,0) | I7: =IF(H6=0,1,SUMPRODUCT(J6:N6,B7:F7)+O6*(1+0.00023125256064071564)) | J7: =IF(G7=1,0.2*R7/B7,J6) | K7: =IF(G7=1,0.2*R7/C7,K6) | L7: =IF(G7=1,0.2*R7/D7,L6) | M7: =IF(G7=1,0.2*R7/E7,M6) | N7: =IF(G7=1,0.2*R7/F7,N6) | O7: =IF(G7=1,R7*(1-1.0),IF(H6=0,1,O6*(1+0.00023125256064071564))) | P7: =IF(G7=1,IF(H6=0,1,ABS(0.2-J6*B7/I7)+ABS(0.2-K6*C7/I7)+ABS(0.2-L6*D7/I7)+ABS(0.2-M6*E7/I7)+ABS(0.2-N6*F7/I7)),0) | Q7: =P7*0.0015 | R7: =I7*(1-Q7) | S7: =R7/R6-1 | T7: =MAX(T6,R7) | U7: =R7/T7-1 | V7: 1 | W7: =R7-V7
A8: 38453 | B8: =Prices!B8 | C8: =Prices!C8 | D8: =Prices!D8 | E8: =Prices!E8 | F8: =Prices!F8 | G8: =IF(AND(6>=16,TEXT(A8,"yyyy-mm")<>TEXT(A9,"yyyy-mm")),1,0) | H8: =IF(OR(H7=1,G8=1),1,0) | I8: =IF(H7=0,1,SUMPRODUCT(J7:N7,B8:F8)+O7*(1+0.00023125256064071564)) | J8: =IF(G8=1,0.2*R8/B8,J7) | K8: =IF(G8=1,0.2*R8/C8,K7) | L8: =IF(G8=1,0.2*R8/D8,L7) | M8: =IF(G8=1,0.2*R8/E8,M7) | N8: =IF(G8=1,0.2*R8/F8,N7) | O8: =IF(G8=1,R8*(1-1.0),IF(H7=0,1,O7*(1+0.00023125256064071564))) | P8: =IF(G8=1,IF(H7=0,1,ABS(0.2-J7*B8/I8)+ABS(0.2-K7*C8/I8)+ABS(0.2-L7*D8/I8)+ABS(0.2-M7*E8/I8)+ABS(0.2-N7*F8/I8)),0) | Q8: =P8*0.0015 | R8: =I8*(1-Q8) | S8: =R8/R7-1 | T8: =MAX(T7,R8) | U8: =R8/T8-1 | V8: 1 | W8: =R8-V8
A9: 38454 | B9: =Prices!B9 | C9: =Prices!C9 | D9: =Prices!D9 | E9: =Prices!E9 | F9: =Prices!F9 | G9: =IF(AND(7>=16,TEXT(A9,"yyyy-mm")<>TEXT(A10,"yyyy-mm")),1,0) | H9: =IF(OR(H8=1,G9=1),1,0) | I9: =IF(H8=0,1,SUMPRODUCT(J8:N8,B9:F9)+O8*(1+0.00023125256064071564)) | J9: =IF(G9=1,0.2*R9/B9,J8) | K9: =IF(G9=1,0.2*R9/C9,K8) | L9: =IF(G9=1,0.2*R9/D9,L8) | M9: =IF(G9=1,0.2*R9/E9,M8) | N9: =IF(G9=1,0.2*R9/F9,N8) | O9: =IF(G9=1,R9*(1-1.0),IF(H8=0,1,O8*(1+0.00023125256064071564))) | P9: =IF(G9=1,IF(H8=0,1,ABS(0.2-J8*B9/I9)+ABS(0.2-K8*C9/I9)+ABS(0.2-L8*D9/I9)+ABS(0.2-M8*E9/I9)+ABS(0.2-N8*F9/I9)),0) | Q9: =P9*0.0015 | R9: =I9*(1-Q9) | S9: =R9/R8-1 | T9: =MAX(T8,R9) | U9: =R9/T9-1 | V9: 1 | W9: =R9-V9
A10: 38455 | B10: =Prices!B10 | C10: =Prices!C10 | D10: =Prices!D10 | E10: =Prices!E10 | F10: =Prices!F10 | G10: =IF(AND(8>=16,TEXT(A10,"yyyy-mm")<>TEXT(A11,"yyyy-mm")),1,0) | H10: =IF(OR(H9=1,G10=1),1,0) | I10: =IF(H9=0,1,SUMPRODUCT(J9:N9,B10:F10)+O9*(1+0.00023125256064071564)) | J10: =IF(G10=1,0.2*R10/B10,J9) | K10: =IF(G10=1,0.2*R10/C10,K9) | L10: =IF(G10=1,0.2*R10/D10,L9) | M10: =IF(G10=1,0.2*R10/E10,M9) | N10: =IF(G10=1,0.2*R10/F10,N9) | O10: =IF(G10=1,R10*(1-1.0),IF(H9=0,1,O9*(1+0.00023125256064071564))) | P10: =IF(G10=1,IF(H9=0,1,ABS(0.2-J9*B10/I10)+ABS(0.2-K9*C10/I10)+ABS(0.2-L9*D10/I10)+ABS(0.2-M9*E10/I10)+ABS(0.2-N9*F10/I10)),0) | Q10: =P10*0.0015 | R10: =I10*(1-Q10) | S10: =R10/R9-1 | T10: =MAX(T9,R10) | U10: =R10/T10-1 | V10: 1 | W10: =R10-V10
A11: 38457 | B11: =Prices!B11 | C11: =Prices!C11 | D11: =Prices!D11 | E11: =Prices!E11 | F11: =Prices!F11 | G11: =IF(AND(9>=16,TEXT(A11,"yyyy-mm")<>TEXT(A12,"yyyy-mm")),1,0) | H11: =IF(OR(H10=1,G11=1),1,0) | I11: =IF(H10=0,1,SUMPRODUCT(J10:N10,B11:F11)+O10*(1+0.00023125256064071564)) | J11: =IF(G11=1,0.2*R11/B11,J10) | K11: =IF(G11=1,0.2*R11/C11,K10) | L11: =IF(G11=1,0.2*R11/D11,L10) | M11: =IF(G11=1,0.2*R11/E11,M10) | N11: =IF(G11=1,0.2*R11/F11,N10) | O11: =IF(G11=1,R11*(1-1.0),IF(H10=0,1,O10*(1+0.00023125256064071564))) | P11: =IF(G11=1,IF(H10=0,1,ABS(0.2-J10*B11/I11)+ABS(0.2-K10*C11/I11)+ABS(0.2-L10*D11/I11)+ABS(0.2-M10*E11/I11)+ABS(0.2-N10*F11/I11)),0) | Q11: =P11*0.0015 | R11: =I11*(1-Q11) | S11: =R11/R10-1 | T11: =MAX(T10,R11) | U11: =R11/T11-1 | V11: 1 | W11: =R11-V11
A12: 38460 | B12: =Prices!B12 | C12: =Prices!C12 | D12: =Prices!D12 | E12: =Prices!E12 | F12: =Prices!F12 | G12: =IF(AND(10>=16,TEXT(A12,"yyyy-mm")<>TEXT(A13,"yyyy-mm")),1,0) | H12: =IF(OR(H11=1,G12=1),1,0) | I12: =IF(H11=0,1,SUMPRODUCT(J11:N11,B12:F12)+O11*(1+0.00023125256064071564)) | J12: =IF(G12=1,0.2*R12/B12,J11) | K12: =IF(G12=1,0.2*R12/C12,K11) | L12: =IF(G12=1,0.2*R12/D12,L11) | M12: =IF(G12=1,0.2*R12/E12,M11) | N12: =IF(G12=1,0.2*R12/F12,N11) | O12: =IF(G12=1,R12*(1-1.0),IF(H11=0,1,O11*(1+0.00023125256064071564))) | P12: =IF(G12=1,IF(H11=0,1,ABS(0.2-J11*B12/I12)+ABS(0.2-K11*C12/I12)+ABS(0.2-L11*D12/I12)+ABS(0.2-M11*E12/I12)+ABS(0.2-N11*F12/I12)),0) | Q12: =P12*0.0015 | R12: =I12*(1-Q12) | S12: =R12/R11-1 | T12: =MAX(T11,R12) | U12: =R12/T12-1 | V12: 1 | W12: =R12-V12
A13: 38461 | B13: =Prices!B13 | C13: =Prices!C13 | D13: =Prices!D13 | E13: =Prices!E13 | F13: =Prices!F13 | G13: =IF(AND(11>=16,TEXT(A13,"yyyy-mm")<>TEXT(A14,"yyyy-mm")),1,0) | H13: =IF(OR(H12=1,G13=1),1,0) | I13: =IF(H12=0,1,SUMPRODUCT(J12:N12,B13:F13)+O12*(1+0.00023125256064071564)) | J13: =IF(G13=1,0.2*R13/B13,J12) | K13: =IF(G13=1,0.2*R13/C13,K12) | L13: =IF(G13=1,0.2*R13/D13,L12) | M13: =IF(G13=1,0.2*R13/E13,M12) | N13: =IF(G13=1,0.2*R13/F13,N12) | O13: =IF(G13=1,R13*(1-1.0),IF(H12=0,1,O12*(1+0.00023125256064071564))) | P13: =IF(G13=1,IF(H12=0,1,ABS(0.2-J12*B13/I13)+ABS(0.2-K12*C13/I13)+ABS(0.2-L12*D13/I13)+ABS(0.2-M12*E13/I13)+ABS(0.2-N12*F13/I13)),0) | Q13: =P13*0.0015 | R13: =I13*(1-Q13) | S13: =R13/R12-1 | T13: =MAX(T12,R13) | U13: =R13/T13-1 | V13: 1 | W13: =R13-V13
A14: 38462 | B14: =Prices!B14 | C14: =Prices!C14 | D14: =Prices!D14 | E14: =Prices!E14 | F14: =Prices!F14 | G14: =IF(AND(12>=16,TEXT(A14,"yyyy-mm")<>TEXT(A15,"yyyy-mm")),1,0) | H14: =IF(OR(H13=1,G14=1),1,0) | I14: =IF(H13=0,1,SUMPRODUCT(J13:N13,B14:F14)+O13*(1+0.00023125256064071564)) | J14: =IF(G14=1,0.2*R14/B14,J13) | K14: =IF(G14=1,0.2*R14/C14,K13) | L14: =IF(G14=1,0.2*R14/D14,L13) | M14: =IF(G14=1,0.2*R14/E14,M13) | N14: =IF(G14=1,0.2*R14/F14,N13) | O14: =IF(G14=1,R14*(1-1.0),IF(H13=0,1,O13*(1+0.00023125256064071564))) | P14: =IF(G14=1,IF(H13=0,1,ABS(0.2-J13*B14/I14)+ABS(0.2-K13*C14/I14)+ABS(0.2-L13*D14/I14)+ABS(0.2-M13*E14/I14)+ABS(0.2-N13*F14/I14)),0) | Q14: =P14*0.0015 | R14: =I14*(1-Q14) | S14: =R14/R13-1 | T14: =MAX(T13,R14) | U14: =R14/T14-1 | V14: 1 | W14: =R14-V14
A15: 38463 | B15: =Prices!B15 | C15: =Prices!C15 | D15: =Prices!D15 | E15: =Prices!E15 | F15: =Prices!F15 | G15: =IF(AND(13>=16,TEXT(A15,"yyyy-mm")<>TEXT(A16,"yyyy-mm")),1,0) | H15: =IF(OR(H14=1,G15=1),1,0) | I15: =IF(H14=0,1,SUMPRODUCT(J14:N14,B15:F15)+O14*(1+0.00023125256064071564)) | J15: =IF(G15=1,0.2*R15/B15,J14) | K15: =IF(G15=1,0.2*R15/C15,K14) | L15: =IF(G15=1,0.2*R15/D15,L14) | M15: =IF(G15=1,0.2*R15/E15,M14) | N15: =IF(G15=1,0.2*R15/F15,N14) | O15: =IF(G15=1,R15*(1-1.0),IF(H14=0,1,O14*(1+0.00023125256064071564))) | P15: =IF(G15=1,IF(H14=0,1,ABS(0.2-J14*B15/I15)+ABS(0.2-K14*C15/I15)+ABS(0.2-L14*D15/I15)+ABS(0.2-M14*E15/I15)+ABS(0.2-N14*F15/I15)),0) | Q15: =P15*0.0015 | R15: =I15*(1-Q15) | S15: =R15/R14-1 | T15: =MAX(T14,R15) | U15: =R15/T15-1 | V15: 1 | W15: =R15-V15
A16: 38464 | B16: =Prices!B16 | C16: =Prices!C16 | D16: =Prices!D16 | E16: =Prices!E16 | F16: =Prices!F16 | G16: =IF(AND(14>=16,TEXT(A16,"yyyy-mm")<>TEXT(A17,"yyyy-mm")),1,0) | H16: =IF(OR(H15=1,G16=1),1,0) | I16: =IF(H15=0,1,SUMPRODUCT(J15:N15,B16:F16)+O15*(1+0.00023125256064071564)) | J16: =IF(G16=1,0.2*R16/B16,J15) | K16: =IF(G16=1,0.2*R16/C16,K15) | L16: =IF(G16=1,0.2*R16/D16,L15) | M16: =IF(G16=1,0.2*R16/E16,M15) | N16: =IF(G16=1,0.2*R16/F16,N15) | O16: =IF(G16=1,R16*(1-1.0),IF(H15=0,1,O15*(1+0.00023125256064071564))) | P16: =IF(G16=1,IF(H15=0,1,ABS(0.2-J15*B16/I16)+ABS(0.2-K15*C16/I16)+ABS(0.2-L15*D16/I16)+ABS(0.2-M15*E16/I16)+ABS(0.2-N15*F16/I16)),0) | Q16: =P16*0.0015 | R16: =I16*(1-Q16) | S16: =R16/R15-1 | T16: =MAX(T15,R16) | U16: =R16/T16-1 | V16: 1 | W16: =R16-V16
A17: 38467 | B17: =Prices!B17 | C17: =Prices!C17 | D17: =Prices!D17 | E17: =Prices!E17 | F17: =Prices!F17 | G17: =IF(AND(15>=16,TEXT(A17,"yyyy-mm")<>TEXT(A18,"yyyy-mm")),1,0) | H17: =IF(OR(H16=1,G17=1),1,0) | I17: =IF(H16=0,1,SUMPRODUCT(J16:N16,B17:F17)+O16*(1+0.00023125256064071564)) | J17: =IF(G17=1,0.2*R17/B17,J16) | K17: =IF(G17=1,0.2*R17/C17,K16) | L17: =IF(G17=1,0.2*R17/D17,L16) | M17: =IF(G17=1,0.2*R17/E17,M16) | N17: =IF(G17=1,0.2*R17/F17,N16) | O17: =IF(G17=1,R17*(1-1.0),IF(H16=0,1,O16*(1+0.00023125256064071564))) | P17: =IF(G17=1,IF(H16=0,1,ABS(0.2-J16*B17/I17)+ABS(0.2-K16*C17/I17)+ABS(0.2-L16*D17/I17)+ABS(0.2-M16*E17/I17)+ABS(0.2-N16*F17/I17)),0) | Q17: =P17*0.0015 | R17: =I17*(1-Q17) | S17: =R17/R16-1 | T17: =MAX(T16,R17) | U17: =R17/T17-1 | V17: 1 | W17: =R17-V17
A18: 38468 | B18: =Prices!B18 | C18: =Prices!C18 | D18: =Prices!D18 | E18: =Prices!E18 | F18: =Prices!F18 | G18: =IF(AND(16>=16,TEXT(A18,"yyyy-mm")<>TEXT(A19,"yyyy-mm")),1,0) | H18: =IF(OR(H17=1,G18=1),1,0) | I18: =IF(H17=0,1,SUMPRODUCT(J17:N17,B18:F18)+O17*(1+0.00023125256064071564)) | J18: =IF(G18=1,0.2*R18/B18,J17) | K18: =IF(G18=1,0.2*R18/C18,K17) | L18: =IF(G18=1,0.2*R18/D18,L17) | M18: =IF(G18=1,0.2*R18/E18,M17) | N18: =IF(G18=1,0.2*R18/F18,N17) | O18: =IF(G18=1,R18*(1-1.0),IF(H17=0,1,O17*(1+0.00023125256064071564))) | P18: =IF(G18=1,IF(H17=0,1,ABS(0.2-J17*B18/I18)+ABS(0.2-K17*C18/I18)+ABS(0.2-L17*D18/I18)+ABS(0.2-M17*E18/I18)+ABS(0.2-N17*F18/I18)),0) | Q18: =P18*0.0015 | R18: =I18*(1-Q18) | S18: =R18/R17-1 | T18: =MAX(T17,R18) | U18: =R18/T18-1 | V18: 1 | W18: =R18-V18
A19: 38469 | B19: =Prices!B19 | C19: =Prices!C19 | D19: =Prices!D19 | E19: =Prices!E19 | F19: =Prices!F19 | G19: =IF(AND(17>=16,TEXT(A19,"yyyy-mm")<>TEXT(A20,"yyyy-mm")),1,0) | H19: =IF(OR(H18=1,G19=1),1,0) | I19: =IF(H18=0,1,SUMPRODUCT(J18:N18,B19:F19)+O18*(1+0.00023125256064071564)) | J19: =IF(G19=1,0.2*R19/B19,J18) | K19: =IF(G19=1,0.2*R19/C19,K18) | L19: =IF(G19=1,0.2*R19/D19,L18) | M19: =IF(G19=1,0.2*R19/E19,M18) | N19: =IF(G19=1,0.2*R19/F19,N18) | O19: =IF(G19=1,R19*(1-1.0),IF(H18=0,1,O18*(1+0.00023125256064071564))) | P19: =IF(G19=1,IF(H18=0,1,ABS(0.2-J18*B19/I19)+ABS(0.2-K18*C19/I19)+ABS(0.2-L18*D19/I19)+ABS(0.2-M18*E19/I19)+ABS(0.2-N18*F19/I19)),0) | Q19: =P19*0.0015 | R19: =I19*(1-Q19) | S19: =R19/R18-1 | T19: =MAX(T18,R19) | U19: =R19/T19-1 | V19: 1 | W19: =R19-V19
A20: 38470 | B20: =Prices!B20 | C20: =Prices!C20 | D20: =Prices!D20 | E20: =Prices!E20 | F20: =Prices!F20 | G20: =IF(AND(18>=16,TEXT(A20,"yyyy-mm")<>TEXT(A21,"yyyy-mm")),1,0) | H20: =IF(OR(H19=1,G20=1),1,0) | I20: =IF(H19=0,1,SUMPRODUCT(J19:N19,B20:F20)+O19*(1+0.00023125256064071564)) | J20: =IF(G20=1,0.2*R20/B20,J19) | K20: =IF(G20=1,0.2*R20/C20,K19) | L20: =IF(G20=1,0.2*R20/D20,L19) | M20: =IF(G20=1,0.2*R20/E20,M19) | N20: =IF(G20=1,0.2*R20/F20,N19) | O20: =IF(G20=1,R20*(1-1.0),IF(H19=0,1,O19*(1+0.00023125256064071564))) | P20: =IF(G20=1,IF(H19=0,1,ABS(0.2-J19*B20/I20)+ABS(0.2-K19*C20/I20)+ABS(0.2-L19*D20/I20)+ABS(0.2-M19*E20/I20)+ABS(0.2-N19*F20/I20)),0) | Q20: =P20*0.0015 | R20: =I20*(1-Q20) | S20: =R20/R19-1 | T20: =MAX(T19,R20) | U20: =R20/T20-1 | V20: 1 | W20: =R20-V20
A21: 38471 | B21: =Prices!B21 | C21: =Prices!C21 | D21: =Prices!D21 | E21: =Prices!E21 | F21: =Prices!F21 | G21: =IF(AND(19>=16,TEXT(A21,"yyyy-mm")<>TEXT(A22,"yyyy-mm")),1,0) | H21: =IF(OR(H20=1,G21=1),1,0) | I21: =IF(H20=0,1,SUMPRODUCT(J20:N20,B21:F21)+O20*(1+0.00023125256064071564)) | J21: =IF(G21=1,0.2*R21/B21,J20) | K21: =IF(G21=1,0.2*R21/C21,K20) | L21: =IF(G21=1,0.2*R21/D21,L20) | M21: =IF(G21=1,0.2*R21/E21,M20) | N21: =IF(G21=1,0.2*R21/F21,N20) | O21: =IF(G21=1,R21*(1-1.0),IF(H20=0,1,O20*(1+0.00023125256064071564))) | P21: =IF(G21=1,IF(H20=0,1,ABS(0.2-J20*B21/I21)+ABS(0.2-K20*C21/I21)+ABS(0.2-L20*D21/I21)+ABS(0.2-M20*E21/I21)+ABS(0.2-N20*F21/I21)),0) | Q21: =P21*0.0015 | R21: =I21*(1-Q21) | S21: =R21/R20-1 | T21: =MAX(T20,R21) | U21: =R21/T21-1 | V21: 0.9985 | W21: =R21-V21
A22: 38474 | B22: =Prices!B22 | C22: =Prices!C22 | D22: =Prices!D22 | E22: =Prices!E22 | F22: =Prices!F22 | G22: =IF(AND(20>=16,TEXT(A22,"yyyy-mm")<>TEXT(A23,"yyyy-mm")),1,0) | H22: =IF(OR(H21=1,G22=1),1,0) | I22: =IF(H21=0,1,SUMPRODUCT(J21:N21,B22:F22)+O21*(1+0.00023125256064071564)) | J22: =IF(G22=1,0.2*R22/B22,J21) | K22: =IF(G22=1,0.2*R22/C22,K21) | L22: =IF(G22=1,0.2*R22/D22,L21) | M22: =IF(G22=1,0.2*R22/E22,M21) | N22: =IF(G22=1,0.2*R22/F22,N21) | O22: =IF(G22=1,R22*(1-1.0),IF(H21=0,1,O21*(1+0.00023125256064071564))) | P22: =IF(G22=1,IF(H21=0,1,ABS(0.2-J21*B22/I22)+ABS(0.2-K21*C22/I22)+ABS(0.2-L21*D22/I22)+ABS(0.2-M21*E22/I22)+ABS(0.2-N21*F22/I22)),0) | Q22: =P22*0.0015 | R22: =I22*(1-Q22) | S22: =R22/R21-1 | T22: =MAX(T21,R22) | U22: =R22/T22-1 | V22: 0.99698393 | W22: =R22-V22
A23: 38475 | B23: =Prices!B23 | C23: =Prices!C23 | D23: =Prices!D23 | E23: =Prices!E23 | F23: =Prices!F23 | G23: =IF(AND(21>=16,TEXT(A23,"yyyy-mm")<>TEXT(A24,"yyyy-mm")),1,0) | H23: =IF(OR(H22=1,G23=1),1,0) | I23: =IF(H22=0,1,SUMPRODUCT(J22:N22,B23:F23)+O22*(1+0.00023125256064071564)) | J23: =IF(G23=1,0.2*R23/B23,J22) | K23: =IF(G23=1,0.2*R23/C23,K22) | L23: =IF(G23=1,0.2*R23/D23,L22) | M23: =IF(G23=1,0.2*R23/E23,M22) | N23: =IF(G23=1,0.2*R23/F23,N22) | O23: =IF(G23=1,R23*(1-1.0),IF(H22=0,1,O22*(1+0.00023125256064071564))) | P23: =IF(G23=1,IF(H22=0,1,ABS(0.2-J22*B23/I23)+ABS(0.2-K22*C23/I23)+ABS(0.2-L22*D23/I23)+ABS(0.2-M22*E23/I23)+ABS(0.2-N22*F23/I23)),0) | Q23: =P23*0.0015 | R23: =I23*(1-Q23) | S23: =R23/R22-1 | T23: =MAX(T22,R23) | U23: =R23/T23-1 | V23: 0.99897922 | W23: =R23-V23
A24: 38476 | B24: =Prices!B24 | C24: =Prices!C24 | D24: =Prices!D24 | E24: =Prices!E24 | F24: =Prices!F24 | G24: =IF(AND(22>=16,TEXT(A24,"yyyy-mm")<>TEXT(A25,"yyyy-mm")),1,0) | H24: =IF(OR(H23=1,G24=1),1,0) | I24: =IF(H23=0,1,SUMPRODUCT(J23:N23,B24:F24)+O23*(1+0.00023125256064071564)) | J24: =IF(G24=1,0.2*R24/B24,J23) | K24: =IF(G24=1,0.2*R24/C24,K23) | L24: =IF(G24=1,0.2*R24/D24,L23) | M24: =IF(G24=1,0.2*R24/E24,M23) | N24: =IF(G24=1,0.2*R24/F24,N23) | O24: =IF(G24=1,R24*(1-1.0),IF(H23=0,1,O23*(1+0.00023125256064071564))) | P24: =IF(G24=1,IF(H23=0,1,ABS(0.2-J23*B24/I24)+ABS(0.2-K23*C24/I24)+ABS(0.2-L23*D24/I24)+ABS(0.2-M23*E24/I24)+ABS(0.2-N23*F24/I24)),0) | Q24: =P24*0.0015 | R24: =I24*(1-Q24) | S24: =R24/R23-1 | T24: =MAX(T23,R24) | U24: =R24/T24-1 | V24: 1.0138275 | W24: =R24-V24
A25: 38477 | B25: =Prices!B25 | C25: =Prices!C25 | D25: =Prices!D25 | E25: =Prices!E25 | F25: =Prices!F25 | G25: =IF(AND(23>=16,TEXT(A25,"yyyy-mm")<>TEXT(A26,"yyyy-mm")),1,0) | H25: =IF(OR(H24=1,G25=1),1,0) | I25: =IF(H24=0,1,SUMPRODUCT(J24:N24,B25:F25)+O24*(1+0.00023125256064071564)) | J25: =IF(G25=1,0.2*R25/B25,J24) | K25: =IF(G25=1,0.2*R25/C25,K24) | L25: =IF(G25=1,0.2*R25/D25,L24) | M25: =IF(G25=1,0.2*R25/E25,M24) | N25: =IF(G25=1,0.2*R25/F25,N24) | O25: =IF(G25=1,R25*(1-1.0),IF(H24=0,1,O24*(1+0.00023125256064071564))) | P25: =IF(G25=1,IF(H24=0,1,ABS(0.2-J24*B25/I25)+ABS(0.2-K24*C25/I25)+ABS(0.2-L24*D25/I25)+ABS(0.2-M24*E25/I25)+ABS(0.2-N24*F25/I25)),0) | Q25: =P25*0.0015 | R25: =I25*(1-Q25) | S25: =R25/R24-1 | T25: =MAX(T24,R25) | U25: =R25/T25-1 | V25: 1.0244485 | W25: =R25-V25
A26: 38478 | B26: =Prices!B26 | C26: =Prices!C26 | D26: =Prices!D26 | E26: =Prices!E26 | F26: =Prices!F26 | G26: =IF(AND(24>=16,TEXT(A26,"yyyy-mm")<>TEXT(A27,"yyyy-mm")),1,0) | H26: =IF(OR(H25=1,G26=1),1,0) | I26: =IF(H25=0,1,SUMPRODUCT(J25:N25,B26:F26)+O25*(1+0.00023125256064071564)) | J26: =IF(G26=1,0.2*R26/B26,J25) | K26: =IF(G26=1,0.2*R26/C26,K25) | L26: =IF(G26=1,0.2*R26/D26,L25) | M26: =IF(G26=1,0.2*R26/E26,M25) | N26: =IF(G26=1,0.2*R26/F26,N25) | O26: =IF(G26=1,R26*(1-1.0),IF(H25=0,1,O25*(1+0.00023125256064071564))) | P26: =IF(G26=1,IF(H25=0,1,ABS(0.2-J25*B26/I26)+ABS(0.2-K25*C26/I26)+ABS(0.2-L25*D26/I26)+ABS(0.2-M25*E26/I26)+ABS(0.2-N25*F26/I26)),0) | Q26: =P26*0.0015 | R26: =I26*(1-Q26) | S26: =R26/R25-1 | T26: =MAX(T25,R26) | U26: =R26/T26-1 | V26: 1.0295725 | W26: =R26-V26
A27: 38481 | B27: =Prices!B27 | C27: =Prices!C27 | D27: =Prices!D27 | E27: =Prices!E27 | F27: =Prices!F27 | G27: =IF(AND(25>=16,TEXT(A27,"yyyy-mm")<>TEXT(A28,"yyyy-mm")),1,0) | H27: =IF(OR(H26=1,G27=1),1,0) | I27: =IF(H26=0,1,SUMPRODUCT(J26:N26,B27:F27)+O26*(1+0.00023125256064071564)) | J27: =IF(G27=1,0.2*R27/B27,J26) | K27: =IF(G27=1,0.2*R27/C27,K26) | L27: =IF(G27=1,0.2*R27/D27,L26) | M27: =IF(G27=1,0.2*R27/E27,M26) | N27: =IF(G27=1,0.2*R27/F27,N26) | O27: =IF(G27=1,R27*(1-1.0),IF(H26=0,1,O26*(1+0.00023125256064071564))) | P27: =IF(G27=1,IF(H26=0,1,ABS(0.2-J26*B27/I27)+ABS(0.2-K26*C27/I27)+ABS(0.2-L26*D27/I27)+ABS(0.2-M26*E27/I27)+ABS(0.2-N26*F27/I27)),0) | Q27: =P27*0.0015 | R27: =I27*(1-Q27) | S27: =R27/R26-1 | T27: =MAX(T26,R27) | U27: =R27/T27-1 | V27: 1.0426492 | W27: =R27-V27
A28: 38482 | B28: =Prices!B28 | C28: =Prices!C28 | D28: =Prices!D28 | E28: =Prices!E28 | F28: =Prices!F28 | G28: =IF(AND(26>=16,TEXT(A28,"yyyy-mm")<>TEXT(A29,"yyyy-mm")),1,0) | H28: =IF(OR(H27=1,G28=1),1,0) | I28: =IF(H27=0,1,SUMPRODUCT(J27:N27,B28:F28)+O27*(1+0.00023125256064071564)) | J28: =IF(G28=1,0.2*R28/B28,J27) | K28: =IF(G28=1,0.2*R28/C28,K27) | L28: =IF(G28=1,0.2*R28/D28,L27) | M28: =IF(G28=1,0.2*R28/E28,M27) | N28: =IF(G28=1,0.2*R28/F28,N27) | O28: =IF(G28=1,R28*(1-1.0),IF(H27=0,1,O27*(1+0.00023125256064071564))) | P28: =IF(G28=1,IF(H27=0,1,ABS(0.2-J27*B28/I28)+ABS(0.2-K27*C28/I28)+ABS(0.2-L27*D28/I28)+ABS(0.2-M27*E28/I28)+ABS(0.2-N27*F28/I28)),0) | Q28: =P28*0.0015 | R28: =I28*(1-Q28) | S28: =R28/R27-1 | T28: =MAX(T27,R28) | U28: =R28/T28-1 | V28: 1.0406986 | W28: =R28-V28
A29: 38483 | B29: =Prices!B29 | C29: =Prices!C29 | D29: =Prices!D29 | E29: =Prices!E29 | F29: =Prices!F29 | G29: =IF(AND(27>=16,TEXT(A29,"yyyy-mm")<>TEXT(A30,"yyyy-mm")),1,0) | H29: =IF(OR(H28=1,G29=1),1,0) | I29: =IF(H28=0,1,SUMPRODUCT(J28:N28,B29:F29)+O28*(1+0.00023125256064071564)) | J29: =IF(G29=1,0.2*R29/B29,J28) | K29: =IF(G29=1,0.2*R29/C29,K28) | L29: =IF(G29=1,0.2*R29/D29,L28) | M29: =IF(G29=1,0.2*R29/E29,M28) | N29: =IF(G29=1,0.2*R29/F29,N28) | O29: =IF(G29=1,R29*(1-1.0),IF(H28=0,1,O28*(1+0.00023125256064071564))) | P29: =IF(G29=1,IF(H28=0,1,ABS(0.2-J28*B29/I29)+ABS(0.2-K28*C29/I29)+ABS(0.2-L28*D29/I29)+ABS(0.2-M28*E29/I29)+ABS(0.2-N28*F29/I29)),0) | Q29: =P29*0.0015 | R29: =I29*(1-Q29) | S29: =R29/R28-1 | T29: =MAX(T28,R29) | U29: =R29/T29-1 | V29: 1.0396584 | W29: =R29-V29
A30: 38484 | B30: =Prices!B30 | C30: =Prices!C30 | D30: =Prices!D30 | E30: =Prices!E30 | F30: =Prices!F30 | G30: =IF(AND(28>=16,TEXT(A30,"yyyy-mm")<>TEXT(A31,"yyyy-mm")),1,0) | H30: =IF(OR(H29=1,G30=1),1,0) | I30: =IF(H29=0,1,SUMPRODUCT(J29:N29,B30:F30)+O29*(1+0.00023125256064071564)) | J30: =IF(G30=1,0.2*R30/B30,J29) | K30: =IF(G30=1,0.2*R30/C30,K29) | L30: =IF(G30=1,0.2*R30/D30,L29) | M30: =IF(G30=1,0.2*R30/E30,M29) | N30: =IF(G30=1,0.2*R30/F30,N29) | O30: =IF(G30=1,R30*(1-1.0),IF(H29=0,1,O29*(1+0.00023125256064071564))) | P30: =IF(G30=1,IF(H29=0,1,ABS(0.2-J29*B30/I30)+ABS(0.2-K29*C30/I30)+ABS(0.2-L29*D30/I30)+ABS(0.2-M29*E30/I30)+ABS(0.2-N29*F30/I30)),0) | Q30: =P30*0.0015 | R30: =I30*(1-Q30) | S30: =R30/R29-1 | T30: =MAX(T29,R30) | U30: =R30/T30-1 | V30: 1.0495132 | W30: =R30-V30
A31: 38485 | B31: =Prices!B31 | C31: =Prices!C31 | D31: =Prices!D31 | E31: =Prices!E31 | F31: =Prices!F31 | G31: =IF(AND(29>=16,TEXT(A31,"yyyy-mm")<>TEXT(A32,"yyyy-mm")),1,0) | H31: =IF(OR(H30=1,G31=1),1,0) | I31: =IF(H30=0,1,SUMPRODUCT(J30:N30,B31:F31)+O30*(1+0.00023125256064071564)) | J31: =IF(G31=1,0.2*R31/B31,J30) | K31: =IF(G31=1,0.2*R31/C31,K30) | L31: =IF(G31=1,0.2*R31/D31,L30) | M31: =IF(G31=1,0.2*R31/E31,M30) | N31: =IF(G31=1,0.2*R31/F31,N30) | O31: =IF(G31=1,R31*(1-1.0),IF(H30=0,1,O30*(1+0.00023125256064071564))) | P31: =IF(G31=1,IF(H30=0,1,ABS(0.2-J30*B31/I31)+ABS(0.2-K30*C31/I31)+ABS(0.2-L30*D31/I31)+ABS(0.2-M30*E31/I31)+ABS(0.2-N30*F31/I31)),0) | Q31: =P31*0.0015 | R31: =I31*(1-Q31) | S31: =R31/R30-1 | T31: =MAX(T30,R31) | U31: =R31/T31-1 | V31: 1.0539999 | W31: =R31-V31
A32: 38488 | B32: =Prices!B32 | C32: =Prices!C32 | D32: =Prices!D32 | E32: =Prices!E32 | F32: =Prices!F32 | G32: =IF(AND(30>=16,TEXT(A32,"yyyy-mm")<>TEXT(A33,"yyyy-mm")),1,0) | H32: =IF(OR(H31=1,G32=1),1,0) | I32: =IF(H31=0,1,SUMPRODUCT(J31:N31,B32:F32)+O31*(1+0.00023125256064071564)) | J32: =IF(G32=1,0.2*R32/B32,J31) | K32: =IF(G32=1,0.2*R32/C32,K31) | L32: =IF(G32=1,0.2*R32/D32,L31) | M32: =IF(G32=1,0.2*R32/E32,M31) | N32: =IF(G32=1,0.2*R32/F32,N31) | O32: =IF(G32=1,R32*(1-1.0),IF(H31=0,1,O31*(1+0.00023125256064071564))) | P32: =IF(G32=1,IF(H31=0,1,ABS(0.2-J31*B32/I32)+ABS(0.2-K31*C32/I32)+ABS(0.2-L31*D32/I32)+ABS(0.2-M31*E32/I32)+ABS(0.2-N31*F32/I32)),0) | Q32: =P32*0.0015 | R32: =I32*(1-Q32) | S32: =R32/R31-1 | T32: =MAX(T31,R32) | U32: =R32/T32-1 | V32: 1.0666264 | W32: =R32-V32
A33: 38489 | B33: =Prices!B33 | C33: =Prices!C33 | D33: =Prices!D33 | E33: =Prices!E33 | F33: =Prices!F33 | G33: =IF(AND(31>=16,TEXT(A33,"yyyy-mm")<>TEXT(A34,"yyyy-mm")),1,0) | H33: =IF(OR(H32=1,G33=1),1,0) | I33: =IF(H32=0,1,SUMPRODUCT(J32:N32,B33:F33)+O32*(1+0.00023125256064071564)) | J33: =IF(G33=1,0.2*R33/B33,J32) | K33: =IF(G33=1,0.2*R33/C33,K32) | L33: =IF(G33=1,0.2*R33/D33,L32) | M33: =IF(G33=1,0.2*R33/E33,M32) | N33: =IF(G33=1,0.2*R33/F33,N32) | O33: =IF(G33=1,R33*(1-1.0),IF(H32=0,1,O32*(1+0.00023125256064071564))) | P33: =IF(G33=1,IF(H32=0,1,ABS(0.2-J32*B33/I33)+ABS(0.2-K32*C33/I33)+ABS(0.2-L32*D33/I33)+ABS(0.2-M32*E33/I33)+ABS(0.2-N32*F33/I33)),0) | Q33: =P33*0.0015 | R33: =I33*(1-Q33) | S33: =R33/R32-1 | T33: =MAX(T32,R33) | U33: =R33/T33-1 | V33: 1.0557218 | W33: =R33-V33
A34: 38490 | B34: =Prices!B34 | C34: =Prices!C34 | D34: =Prices!D34 | E34: =Prices!E34 | F34: =Prices!F34 | G34: =IF(AND(32>=16,TEXT(A34,"yyyy-mm")<>TEXT(A35,"yyyy-mm")),1,0) | H34: =IF(OR(H33=1,G34=1),1,0) | I34: =IF(H33=0,1,SUMPRODUCT(J33:N33,B34:F34)+O33*(1+0.00023125256064071564)) | J34: =IF(G34=1,0.2*R34/B34,J33) | K34: =IF(G34=1,0.2*R34/C34,K33) | L34: =IF(G34=1,0.2*R34/D34,L33) | M34: =IF(G34=1,0.2*R34/E34,M33) | N34: =IF(G34=1,0.2*R34/F34,N33) | O34: =IF(G34=1,R34*(1-1.0),IF(H33=0,1,O33*(1+0.00023125256064071564))) | P34: =IF(G34=1,IF(H33=0,1,ABS(0.2-J33*B34/I34)+ABS(0.2-K33*C34/I34)+ABS(0.2-L33*D34/I34)+ABS(0.2-M33*E34/I34)+ABS(0.2-N33*F34/I34)),0) | Q34: =P34*0.0015 | R34: =I34*(1-Q34) | S34: =R34/R33-1 | T34: =MAX(T33,R34) | U34: =R34/T34-1 | V34: 1.0562474 | W34: =R34-V34
A35: 38491 | B35: =Prices!B35 | C35: =Prices!C35 | D35: =Prices!D35 | E35: =Prices!E35 | F35: =Prices!F35 | G35: =IF(AND(33>=16,TEXT(A35,"yyyy-mm")<>TEXT(A36,"yyyy-mm")),1,0) | H35: =IF(OR(H34=1,G35=1),1,0) | I35: =IF(H34=0,1,SUMPRODUCT(J34:N34,B35:F35)+O34*(1+0.00023125256064071564)) | J35: =IF(G35=1,0.2*R35/B35,J34) | K35: =IF(G35=1,0.2*R35/C35,K34) | L35: =IF(G35=1,0.2*R35/D35,L34) | M35: =IF(G35=1,0.2*R35/E35,M34) | N35: =IF(G35=1,0.2*R35/F35,N34) | O35: =IF(G35=1,R35*(1-1.0),IF(H34=0,1,O34*(1+0.00023125256064071564))) | P35: =IF(G35=1,IF(H34=0,1,ABS(0.2-J34*B35/I35)+ABS(0.2-K34*C35/I35)+ABS(0.2-L34*D35/I35)+ABS(0.2-M34*E35/I35)+ABS(0.2-N34*F35/I35)),0) | Q35: =P35*0.0015 | R35: =I35*(1-Q35) | S35: =R35/R34-1 | T35: =MAX(T34,R35) | U35: =R35/T35-1 | V35: 1.0643816 | W35: =R35-V35
A36: 38492 | B36: =Prices!B36 | C36: =Prices!C36 | D36: =Prices!D36 | E36: =Prices!E36 | F36: =Prices!F36 | G36: =IF(AND(34>=16,TEXT(A36,"yyyy-mm")<>TEXT(A37,"yyyy-mm")),1,0) | H36: =IF(OR(H35=1,G36=1),1,0) | I36: =IF(H35=0,1,SUMPRODUCT(J35:N35,B36:F36)+O35*(1+0.00023125256064071564)) | J36: =IF(G36=1,0.2*R36/B36,J35) | K36: =IF(G36=1,0.2*R36/C36,K35) | L36: =IF(G36=1,0.2*R36/D36,L35) | M36: =IF(G36=1,0.2*R36/E36,M35) | N36: =IF(G36=1,0.2*R36/F36,N35) | O36: =IF(G36=1,R36*(1-1.0),IF(H35=0,1,O35*(1+0.00023125256064071564))) | P36: =IF(G36=1,IF(H35=0,1,ABS(0.2-J35*B36/I36)+ABS(0.2-K35*C36/I36)+ABS(0.2-L35*D36/I36)+ABS(0.2-M35*E36/I36)+ABS(0.2-N35*F36/I36)),0) | Q36: =P36*0.0015 | R36: =I36*(1-Q36) | S36: =R36/R35-1 | T36: =MAX(T35,R36) | U36: =R36/T36-1 | V36: 1.063549 | W36: =R36-V36
A37: 38495 | B37: =Prices!B37 | C37: =Prices!C37 | D37: =Prices!D37 | E37: =Prices!E37 | F37: =Prices!F37 | G37: =IF(AND(35>=16,TEXT(A37,"yyyy-mm")<>TEXT(A38,"yyyy-mm")),1,0) | H37: =IF(OR(H36=1,G37=1),1,0) | I37: =IF(H36=0,1,SUMPRODUCT(J36:N36,B37:F37)+O36*(1+0.00023125256064071564)) | J37: =IF(G37=1,0.2*R37/B37,J36) | K37: =IF(G37=1,0.2*R37/C37,K36) | L37: =IF(G37=1,0.2*R37/D37,L36) | M37: =IF(G37=1,0.2*R37/E37,M36) | N37: =IF(G37=1,0.2*R37/F37,N36) | O37: =IF(G37=1,R37*(1-1.0),IF(H36=0,1,O36*(1+0.00023125256064071564))) | P37: =IF(G37=1,IF(H36=0,1,ABS(0.2-J36*B37/I37)+ABS(0.2-K36*C37/I37)+ABS(0.2-L36*D37/I37)+ABS(0.2-M36*E37/I37)+ABS(0.2-N36*F37/I37)),0) | Q37: =P37*0.0015 | R37: =I37*(1-Q37) | S37: =R37/R36-1 | T37: =MAX(T36,R37) | U37: =R37/T37-1 | V37: 1.0701266 | W37: =R37-V37
A38: 38496 | B38: =Prices!B38 | C38: =Prices!C38 | D38: =Prices!D38 | E38: =Prices!E38 | F38: =Prices!F38 | G38: =IF(AND(36>=16,TEXT(A38,"yyyy-mm")<>TEXT(A39,"yyyy-mm")),1,0) | H38: =IF(OR(H37=1,G38=1),1,0) | I38: =IF(H37=0,1,SUMPRODUCT(J37:N37,B38:F38)+O37*(1+0.00023125256064071564)) | J38: =IF(G38=1,0.2*R38/B38,J37) | K38: =IF(G38=1,0.2*R38/C38,K37) | L38: =IF(G38=1,0.2*R38/D38,L37) | M38: =IF(G38=1,0.2*R38/E38,M37) | N38: =IF(G38=1,0.2*R38/F38,N37) | O38: =IF(G38=1,R38*(1-1.0),IF(H37=0,1,O37*(1+0.00023125256064071564))) | P38: =IF(G38=1,IF(H37=0,1,ABS(0.2-J37*B38/I38)+ABS(0.2-K37*C38/I38)+ABS(0.2-L37*D38/I38)+ABS(0.2-M37*E38/I38)+ABS(0.2-N37*F38/I38)),0) | Q38: =P38*0.0015 | R38: =I38*(1-Q38) | S38: =R38/R37-1 | T38: =MAX(T37,R38) | U38: =R38/T38-1 | V38: 1.0745958 | W38: =R38-V38
A39: 38497 | B39: =Prices!B39 | C39: =Prices!C39 | D39: =Prices!D39 | E39: =Prices!E39 | F39: =Prices!F39 | G39: =IF(AND(37>=16,TEXT(A39,"yyyy-mm")<>TEXT(A40,"yyyy-mm")),1,0) | H39: =IF(OR(H38=1,G39=1),1,0) | I39: =IF(H38=0,1,SUMPRODUCT(J38:N38,B39:F39)+O38*(1+0.00023125256064071564)) | J39: =IF(G39=1,0.2*R39/B39,J38) | K39: =IF(G39=1,0.2*R39/C39,K38) | L39: =IF(G39=1,0.2*R39/D39,L38) | M39: =IF(G39=1,0.2*R39/E39,M38) | N39: =IF(G39=1,0.2*R39/F39,N38) | O39: =IF(G39=1,R39*(1-1.0),IF(H38=0,1,O38*(1+0.00023125256064071564))) | P39: =IF(G39=1,IF(H38=0,1,ABS(0.2-J38*B39/I39)+ABS(0.2-K38*C39/I39)+ABS(0.2-L38*D39/I39)+ABS(0.2-M38*E39/I39)+ABS(0.2-N38*F39/I39)),0) | Q39: =P39*0.0015 | R39: =I39*(1-Q39) | S39: =R39/R38-1 | T39: =MAX(T38,R39) | U39: =R39/T39-1 | V39: 1.0797647 | W39: =R39-V39
A40: 38498 | B40: =Prices!B40 | C40: =Prices!C40 | D40: =Prices!D40 | E40: =Prices!E40 | F40: =Prices!F40 | G40: =IF(AND(38>=16,TEXT(A40,"yyyy-mm")<>TEXT(A41,"yyyy-mm")),1,0) | H40: =IF(OR(H39=1,G40=1),1,0) | I40: =IF(H39=0,1,SUMPRODUCT(J39:N39,B40:F40)+O39*(1+0.00023125256064071564)) | J40: =IF(G40=1,0.2*R40/B40,J39) | K40: =IF(G40=1,0.2*R40/C40,K39) | L40: =IF(G40=1,0.2*R40/D40,L39) | M40: =IF(G40=1,0.2*R40/E40,M39) | N40: =IF(G40=1,0.2*R40/F40,N39) | O40: =IF(G40=1,R40*(1-1.0),IF(H39=0,1,O39*(1+0.00023125256064071564))) | P40: =IF(G40=1,IF(H39=0,1,ABS(0.2-J39*B40/I40)+ABS(0.2-K39*C40/I40)+ABS(0.2-L39*D40/I40)+ABS(0.2-M39*E40/I40)+ABS(0.2-N39*F40/I40)),0) | Q40: =P40*0.0015 | R40: =I40*(1-Q40) | S40: =R40/R39-1 | T40: =MAX(T39,R40) | U40: =R40/T40-1 | V40: 1.0795379 | W40: =R40-V40
...

Sheet Metrics
A1: Metric | B1: Excel (live formula) | C1: Note
A2: Final NAV | B2: =Backtest!R5257 | C2: grew from 1.00
A3: CAGR | B3: =(Backtest!R5257/Backtest!R2)^(1/((Backtest!A5257-Backtest!A2)/365.25))-1
A4: Annualised volatility | B4: =STDEV.S(Backtest!S2:S5257)*SQRT(252) | C4: sample sd x sqrt(252)
A5: Max drawdown | B5: =-MIN(Backtest!U2:U5257)
A6: Compounded cash return (CAGR) | B6: =((1+0.00023125256064071564)^(5256/((Backtest!A5257-Backtest!A2)/365.25))-1) | C6: flat proxy -- see READ ME
A7: Sharpe (geometric, paper definition) | B7: =(B3-B6)/B4 | C7: (CAGR - cash) / vol
A8: Sharpe (conventional) | B8: =(AVERAGE(Backtest!S2:S5257)-0.00023125256064071564)/STDEV.S(Backtest!S2:S5257)*SQRT(252) | C8: mean excess / sd
A9: Total cost paid (fraction of NAV) | B9: =SUM(Backtest!Q2:Q5257)
A10: Total turnover (one-way) | B10: =SUM(Backtest!P2:P5257)/2
A11: Number of rebalances | B11: =SUM(Backtest!G2:G5257)
A13: LARGEST NAV DIFFERENCE vs engine | B13: =MAX(MAX(Backtest!W2:W5257),-MIN(Backtest!W2:W5257)) | C13: should be ~1e-15
